Workbook

Sheet Shafts e Afins
B1: Manifold | E1: Convencional
B2: Vazão | C2: 12 | E2: Vazão | F2: =C2 | J2: =C2/60 | M2: Tabela Caleffi
B3: Pontos simultâneo | C3: 1 | E3: Pontos simultâneo | F3: 1 | M3: Diâmetro | N3: Velocidade | O3: Vazão máxima
B4: Vazão total | C4: =C2*C3 | E4: Vazão total | F4: =F2*F3 | J4: =F4/60 | O4: CPVC | P4: PPR | Q4: PVC
B5: Diâmetro CPVC | C5: 22 | E5: Diâmetro CPVC | F5: 35 | M5: ½” | N5: 1 | O5: =(3.14*N5*(Planilha2!B5/1000)^2/4)*60000
B6: Diâmetro interno CPVC | C6: =INDEX(Planilha2!$B$5:$B$13,MATCH(C5,Planilha2!$A$5:$A$13,0)) | E6: Diâmetro interno CPVC | F6: =INDEX(Planilha2!$B$5:$B$13,MATCH(F5,Planilha2!$A$5:$A$13,0)) | J6: =F6/1000 | M6: ¾” | N6: 1.1 | O6: =(3.14*N6*(Planilha2!B6/1000)^2/4)*60000
M7: 1” | N7: 1.3 | O7: =(3.14*N7*(Planilha2!B7/1000)^2/4)*60000
M8: 1.1/4” | N8: 1.6 | O8: =(3.14*N8*(Planilha2!B8/1000)^2/4)*60000
B9: Distância | C9: 20 | E9: Distância | F9: =C9 | M9: 1.1/2” | N9: 1.8 | O9: =(3.14*N9*(Planilha2!B9/1000)^2/4)*60000
B10: Área | C10: =((C6/1000)^2*3.14)/4 | E10: Área | F10: =((F6/1000)^2*3.14)/4 | M10: 2” | N10: 2 | O10: =(3.14*N10*(Planilha2!B10/1000)^2/4)*60000
B11: Velocidade | C11: =(4*(C2/60)/1000)/(3.14*(C6/1000)^2) | E11: Velocidade | F11: =(4*(F4/60)/1000)/(3.14*(F6/1000)^2) | M11: 2.1/2” | N11: 2.2 | O11: =(3.14*N11*(Planilha2!B11/1000)^2/4)*60000
B12: Tempo | C12: =(((C9/C11)/60)/60)*(1/24) | E12: Tempo | F12: =(((F9/F11)/60)/60)*(1/24) | M12: 3” | N12: 2.5 | O12: =(3.14*N12*(Planilha2!B12/1000)^2/4)*60000
B13: Volume | C13: =(C10*C9)*1000 | E13: Volume | F13: =(F10*F9)*1000
B15: Temperatura Ambiente | C15: 10 | E15: Temperatura Ambiente | F15: =C15 | J15: armaflex
B16: Temperatura Final | C16: 45 | E16: Temperatura Final | F16: =C16 | J16: 6
B17: Condutividade Térmica CPVC | C17: 0.14 | E17: Condutividade Térmica CPVC | F17: 0.14 | J17: 10
B18: Condutividade térmica Isolante | C18: 0.036 | E18: Condutividade térmica Isolante | F18: 0.036 | J18: 13
B19: Espessura | C19: 9 | E19: Espessura | F19: 0 | J19: 19
B20: Perda de carga térmica Tubos | C20: =IF(C19=0,((2*3.14*(C9)*(C15-C16))/((1/C17)*(LN(C5/C6))))/1000,((2*3.14*(C9)*(C15-C16))/(((1/C17)*(LN(C5/C6))+((1/C18)*(LN((C5+2*C19)/C5)))))/1000)) | E20: Perda de carga térmica Tubos | F20: =IF(F19=0,((2*3.14*(F9)*(F15-F16))/((1/F17)*(LN(F5/F6))))/1000,((2*3.14*(F9)*(F15-F16))/(((1/F17)*(LN(F5/F6))+((1/F18)*(LN((F5+2*F19)/F5)))))/1000)) | J20: 25
B21: Perda água parada (kcal) | C21: =C13*(C15-C16) | E21: Perda água parada (kcal) | F21: =F13*(F15-F16) | J21: 32
J22: 50
B23: h externo | C23: 8 | E23: h externo | F23: =C23
B24: Vazão mássica | C24: =C4/60 | E24: Vazão mássica | F24: =F4/60
B25: Calor específico água | C25: =4186 | E25: Calor específico água | F25: =4186
B26: R convecção interna | C26: =1/(C53*2*PI()*(C6/1000/2)*C9) | E26: R convecção interna | F26: =1/(F53*2*PI()*(F6/1000/2)*F9)
B27: R tubo CPVC | C27: =LN(C5/C6)/(2*PI()*C17*C9) | E27: R tubo CPVC | F27: =LN(F5/F6)/(2*PI()*F17*F9)
B28: R isolante | C28: =IF(C19=0,0,LN((C5+2*C19)/C5)/(2*PI()*C18*C9)) | E28: R isolante | F28: =IF(F19=0,0,LN((F5+2*F19)/F5)/(2*PI()*F18*F9))
B29: Diâmetro externo final | C29: =(C5+2*C19)/1000 | E29: Diâmetro externo final | F29: =(F5+2*F19)/1000
B30: R convecção externa | C30: =1/(C23*PI()*C29*C9) | E30: R convecção externa | F30: =1/(F23*PI()*F29*F9)
B32: R total | C32: =C26+C27+C28+C30 | E32: R total | F32: =F26+F27+F28+F30
B33: UA | C33: =1/C32 | E33: UA | F33: =1/F32
B34: Perda real da água | C34: =(C16-C15)*(1-EXP(-C33/(C24*C25))) | E34: Perda real da água | F34: =(F16-F15)*(1-EXP(-F33/(F24*F25)))
B35: Temperatura final real | C35: =C16-C34 | E35: Temperatura final real | F35: =F16-F34
B37: Capacidade térmica da água parada | C37: =C13*4186 | E37: Capacidade térmica da água parada | F37: =F13*4186
B38: Constante térmica τ | C38: =C32*C37 | E38: Constante térmica τ | F38: =F32*F37
B39: Tempo parado | C39: 20 | E39: Tempo parado | F39: =C39
B40: Temperatura após X minutos | C40: =C15+(C35-C15)*EXP(-(C39*60)/C38) | E40: Temperatura após X minutos | F40: =F15+(F35-F15)*EXP(-(F39*60)/F38)
B42: Temperatura alvo (teste) | C42: 35 | E42: Temperatura alvo (teste) | F42: 35
B43: Tempo p/ chegar na temp. alvo | C43: =-C38*LN((C42-C15)/(C16-C15))/60 | E43: Tempo p/ chegar na temp. alvo | F43: =-F38*LN((F42-F15)/(F16-F15))/60
B49: Visc. cinemática | C49: 8e-07 | E49: Visc. cinemática | F49: 8e-07
...

Sheet Planilha2
A1: Diâmetro interno CPVC
A2: Diâmetro Comercial | B2: Diâmetro interno
A5: 15 | B5: =A5-1.6-1.6
A6: 22 | B6: =A6-2.2-2.2
A7: 28 | B7: =A7-2.7-2.7
A8: 35 | B8: =A8-3.2-3.2
A9: 42 | B9: =A9-3.8-3.8
A10: 54 | B10: =A10-4.9-4.9
A11: 73 | B11: =A11-6.9-6.9
A12: 89 | B12: =A12-8.5-8.5
A13: 114 | B13: =A13-10.4-10.4

Sheet Ambientes
A1: Ambiente | B1: h externo (W/m²·K)
A2: Ambiente interno parado | B2: 3
A3: Forro | B3: 5
A4: Shaft técnico | B4: 7
A5: Embutido em parede | B5: 4
A6: Ar livre sem vento | B6: 12
A7: Ar livre moderado | B7: 20
A8: Ar livre vento forte | B8: 35

Sheet Solos
B1: Manifold | E1: Convencional
B2: Vazão | C2: 12 | E2: Vazão | F2: =C2 | J2: =C2/60 | M2: Tabela Caleffi
B3: Pontos simultâneo | C3: 1 | E3: Pontos simultâneo | F3: =C3 | M3: Diâmetro | N3: Velocidade | O3: Vazão máxima
B4: Vazão total | C4: =C2*C3 | E4: Vazão total | F4: =F2*F3 | J4: =F4/60 | O4: CPVC | P4: PPR | Q4: PVC
B5: Diâmetro CPVC | C5: 22 | E5: Diâmetro CPVC | F5: 42 | M5: ½” | N5: 1 | O5: =(3.14*N5*(Planilha2!B5/1000)^2/4)*60000
B6: Diâmetro interno CPVC | C6: =INDEX(Planilha2!$B$5:$B$13,MATCH(C5,Planilha2!$A$5:$A$13,0)) | E6: Diâmetro interno CPVC | F6: =INDEX(Planilha2!$B$5:$B$13,MATCH(F5,Planilha2!$A$5:$A$13,0)) | J6: =F6/1000 | M6: ¾” | N6: 1.1 | O6: =(3.14*N6*(Planilha2!B6/1000)^2/4)*60000
M7: 1” | N7: 1.3 | O7: =(3.14*N7*(Planilha2!B7/1000)^2/4)*60000
M8: 1.1/4” | N8: 1.6 | O8: =(3.14*N8*(Planilha2!B8/1000)^2/4)*60000
B9: Distância | C9: 20 | E9: Distância | F9: =C9 | M9: 1.1/2” | N9: 1.8 | O9: =(3.14*N9*(Planilha2!B9/1000)^2/4)*60000
B10: Área | C10: =((C6/1000)^2*3.14)/4 | E10: Área | F10: =((F6/1000)^2*3.14)/4 | M10: 2” | N10: 2 | O10: =(3.14*N10*(Planilha2!B10/1000)^2/4)*60000
B11: Velocidade | C11: =(4*(C2/60)/1000)/(3.14*(C6/1000)^2) | E11: Velocidade | F11: =(4*(F4/60)/1000)/(3.14*(F6/1000)^2) | M11: 2.1/2” | N11: 2.2 | O11: =(3.14*N11*(Planilha2!B11/1000)^2/4)*60000
B12: Tempo | C12: =(((C9/C11)/60)/60)*(1/24) | E12: Tempo | F12: =(((F9/F11)/60)/60)*(1/24) | M12: 3” | N12: 2.5 | O12: =(3.14*N12*(Planilha2!B12/1000)^2/4)*60000
B13: Volume | C13: =(C10*C9)*1000 | E13: Volume | F13: =(F10*F9)*1000
B15: Temperatura Ambiente | C15: 10 | E15: Temperatura Ambiente | F15: =C15 | J15: armaflex
B16: Temperatura Final | C16: 45 | E16: Temperatura Final | F16: =C16 | J16: 6
B17: Condutividade Térmica CPVC | C17: 0.14 | E17: Condutividade Térmica CPVC | F17: 0.14 | J17: 10
B18: Condutividade térmica Isolante | C18: 0.036 | E18: Condutividade térmica Isolante | F18: 0.036 | J18: 13
B19: Espessura | C19: 0 | E19: Espessura | F19: 0 | J19: 19
B20: Perda de carga térmica Tubos | C20: =IF(C19=0,((2*3.14*(C9)*(C15-C16))/((1/C17)*(LN(C5/C6))))/1000,((2*3.14*(C9)*(C15-C16))/(((1/C17)*(LN(C5/C6))+((1/C18)*(LN((C5+2*C19)/C5)))))/1000)) | E20: Perda de carga térmica Tubos | F20: =IF(F19=0,((2*3.14*(F9)*(F15-F16))/((1/F17)*(LN(F5/F6))))/1000,((2*3.14*(F9)*(F15-F16))/(((1/F17)*(LN(F5/F6))+((1/F18)*(LN((F5+2*F19)/F5)))))/1000)) | J20: 25
B21: Perda água parada (kcal) | C21: =C13*(C15-C16) | E21: Perda água parada (kcal) | F21: =F13*(F15-F16) | J21: 32
J22: 50
B23: Condutividade solo | C23: 1.5 | E23: Condutividade solo | F23: =C23
B24: Vazão mássica | C24: =C4/60 | E24: Vazão mássica | F24: =F4/60
B25: Raio influência solo | C25: 0.5 | E25: Raio influência solo | F25: =C25
B26: Calor específico água | C26: 4186 | E26: Calor específico água | F26: 4186
B27: R convecção interna | C27: =1/(C56*2*PI()*(C6/1000/2)*C9) | E27: R convecção interna | F27: =1/(F56*2*PI()*(F6/1000/2)*F9)
B28: R tubo CPVC | C28: =LN(C5/C6)/(2*PI()*C17*C9) | E28: R tubo CPVC | F28: =LN(F5/F6)/(2*PI()*F17*F9)
B29: R isolante | C29: =IF(C19=0,0,LN((C5+2*C19)/C5)/(2*PI()*C18*C9)) | E29: R isolante | F29: =IF(F19=0,0,LN((F5+2*F19)/F5)/(2*PI()*F18*F9))
B30: Diâmetro externo final | C30: =(C5+2*C19)/1000 | E30: Diâmetro externo final | F30: =(F5+2*F19)/1000
B31: R solo | C31: =LN(C25/(C30/2))/(2*PI()*C23*C9) | E31: R solo | F31: =LN(F25/(F30/2))/(2*PI()*F23*F9)
B33: R total | C33: =C27+C28+C29+C31 | E33: R total | F33: =F27+F28+F29+F31
B34: UA | C34: =1/C33 | E34: UA | F34: =1/F33
B35: Perda real da água | C35: =(C16-C15)*(1-EXP(-C34/(C24*C26))) | E35: Perda real da água | F35: =(F16-F15)*(1-EXP(-F34/(F24*F26)))
B36: Temperatura final real | C36: =C16-C35 | E36: Temperatura final real | F36: =F16-F35
B38: Capacidade térmica da água parada | C38: =C13*4186 | E38: Capacidade térmica da água parada | F38: =F13*4186
B39: Constante térmica τ | C39: =C33*C38 | E39: Constante térmica τ | F39: =F33*F38
B40: Tempo parado | C40: 20 | E40: Tempo parado | F40: 20
B41: Temperatura após X minutos | C41: =C15+(C36-C15)*EXP(-(C40*60)/C39) | E41: Temperatura após X minutos | F41: =F15+(F36-F15)*EXP(-(F40*60)/F39)
B43: Temperatura alvo (teste) | C43: 35 | E43: Temperatura alvo (teste) | F43: 35
B44: Tempo p/ chegar na temp. alvo | C44: =-C39*LN((C43-C15)/(C16-C15))/60 | E44: Tempo p/ chegar na temp. alvo | F44: =-F39*LN((F43-F15)/(F16-F15))/60
...

Sheet Coef. Solos
B2: Condutividade solo
B3: Tipo de solo | C3: (k) recomendado (W/m·K) | D3: Descrição prática | E3: Característica térmica | F3: Quando usar
B4: Solo seco / arenoso | C4: 0.5 | D4: Terra seca, areia, solo fofo, pouca umidade | E4: Solo conduz pouco calor | F4: Regiões secas, tubulação rasa em jardim seco
B5: Solo residencial padrão | C5: 1 | D5: Terra compactada comum de obra residencial | E5: Condição intermediária mais realista | F5: Padrão recomendado para maioria das casas
B6: Solo úmido | C6: 1.5 | D6: Terra constantemente úmida, irrigada ou sombreada | E6: Água aumenta muito a condução térmica | F6: Jardins irrigados, áreas úmidas
B7: Solo muito úmido / saturado | C7: 2 | D7: Solo encharcado ou próximo de lençol freático | E7: Solo começa atuar como dissipador forte | F7: Lençol freático, áreas alagáveis
B9: Raio influência solo
B10: Raio influência | C10: Descrição prática | D10: Equivalência prática | E10: Característica térmica | F10: Quando usar
B11: 0,15 m | C11: Enterrado raso | D11: Tubo enterrado entre 5–15 cm de profundidade | E11: Pouca massa de solo ao redor | F11: Jardim superficial, passagem rasa
B12: 0,30 m | C12: Residencial padrão | D12: Tubo enterrado ~20–40 cm | E12: Massa térmica intermediária | F12: Obras residenciais comuns
B13: 0,50 m | C13: Enterrado profundo / solo massivo | D13: Tubo enterrado >50 cm ou muito envolvido por solo/concreto | E13: Grande massa térmica ao redor | F13: Tubo profundo, contrapiso, solo muito estável

Sheet _Correções
A1: Correções aplicadas (vs arquivo original) — Hidráulica de Casas
A2: Gerado para uso como fonte de verdade da ferramenta. Original preservado separadamente.
A4: Aba | B4: Célula | C4: Fórmula ANTES | D4: Fórmula DEPOIS | E4: Status | F4: Motivo
A5: Solos | B5: C41 | C5: =C16+(C36-C16)*EXP(-(C40*60)/C39) | D5: =C15+(C36-C15)*EXP(-(C40*60)/C39) | E5: alterado | F5: Resfriamento: asíntota = temp ambiente C15 (era C16)
A6: Solos | B6: F41 | C6: =F16+(F36-F16)*EXP(-(F40*60)/F39) | D6: =F15+(F36-F15)*EXP(-(F40*60)/F39) | E6: alterado | F6: Resfriamento: asíntota = temp ambiente F15 (era F16)
A7: Solos | B7: C44 | C7: =-C39*LN((C43-C16)/(C17-C16))/60 | D7: =-C39*LN((C43-C15)/(C16-C15))/60 | E7: alterado | F7: Tempo p/ alvo: usar C15 ambiente e C16 inicial (era C16/C17=condutividade)
A8: Solos | B8: F44 | C8: =-F39*LN((F43-F16)/(F17-F16))/60 | D8: =-F39*LN((F43-F15)/(F16-F15))/60 | E8: alterado | F8: Tempo p/ alvo: usar F15 ambiente e F16 inicial (era F16/F17=condutividade)
A9: Shafts e Afins | B9: C6 | C9: =INDEX(Planilha2!$B$5:$B$13,MATCH(C5,Planilha2!$A$5:$A$13,2)) | D9: =INDEX(Planilha2!$B$5:$B$13,MATCH(C5,Planilha2!$A$5:$A$13,0)) | E9: alterado | F9: MATCH exato (3o arg 0) no lugar de 2
A10: Shafts e Afins | B10: F6 | C10: =INDEX(Planilha2!$B$5:$B$13,MATCH(F5,Planilha2!$A$5:$A$13,2)) | D10: =INDEX(Planilha2!$B$5:$B$13,MATCH(F5,Planilha2!$A$5:$A$13,0)) | E10: alterado | F10: MATCH exato (3o arg 0) no lugar de 2
A11: Solos | B11: C6 | C11: =INDEX(Planilha2!$B$5:$B$13,MATCH(C5,Planilha2!$A$5:$A$13,2)) | D11: =INDEX(Planilha2!$B$5:$B$13,MATCH(C5,Planilha2!$A$5:$A$13,0)) | E11: alterado | F11: MATCH exato (3o arg 0) no lugar de 2
A12: Solos | B12: F6 | C12: =INDEX(Planilha2!$B$5:$B$13,MATCH(F5,Planilha2!$A$5:$A$13,2)) | D12: =INDEX(Planilha2!$B$5:$B$13,MATCH(F5,Planilha2!$A$5:$A$13,0)) | E12: alterado | F12: MATCH exato (3o arg 0) no lugar de 2
A13: Shafts e Afins | B13: C20 | C13: =IF(C19=0,((2*3.14*(C9)*(C15-C16))/((1/C17)*(LN(C5/C6))))/1000,((2*3.14*(C9)*(C15-C16))/(((1/C17)*(LN(C5/C6))+((1/C18)*(LN((C5+C19)/C5)))))/1000)) | D13: =IF(C19=0,((2*3.14*(C9)*(C15-C16))/((1/C17)*(LN(C5/C6))))/1000,((2*3.14*(C9)*(C15-C16))/(((1/C17)*(LN(C5/C6))+((1/C18)*(LN((C5+2*C19)/C5)))))/1000)) | E13: alterado | F13: Isolante: diâmetro externo = C5+2*C19 (era C5+C19)
A14: Shafts e Afins | B14: F20 | C14: =IF(F19=0,((2*3.14*(F9)*(F15-F16))/((1/F17)*(LN(F5/F6))))/1000,((2*3.14*(F9)*(F15-F16))/(((1/F17)*(LN(F5/F6))+((1/F18)*(LN((F5+F19)/F5)))))/1000)) | D14: =IF(F19=0,((2*3.14*(F9)*(F15-F16))/((1/F17)*(LN(F5/F6))))/1000,((2*3.14*(F9)*(F15-F16))/(((1/F17)*(LN(F5/F6))+((1/F18)*(LN((F5+2*F19)/F5)))))/1000)) | E14: alterado | F14: Isolante: diâmetro externo = F5+2*F19 (era F5+F19)
A15: Solos | B15: C20 | C15: =IF(C19=0,((2*3.14*(C9)*(C15-C16))/((1/C17)*(LN(C5/C6))))/1000,((2*3.14*(C9)*(C15-C16))/(((1/C17)*(LN(C5/C6))+((1/C18)*(LN((C5+C19)/C5)))))/1000)) | D15: =IF(C19=0,((2*3.14*(C9)*(C15-C16))/((1/C17)*(LN(C5/C6))))/1000,((2*3.14*(C9)*(C15-C16))/(((1/C17)*(LN(C5/C6))+((1/C18)*(LN((C5+2*C19)/C5)))))/1000)) | E15: alterado | F15: Isolante: diâmetro externo = C5+2*C19 (era C5+C19)
A16: Solos | B16: F20 | C16: =IF(F19=0,((2*3.14*(F9)*(F15-F16))/((1/F17)*(LN(F5/F6))))/1000,((2*3.14*(F9)*(F15-F16))/(((1/F17)*(LN(F5/F6))+((1/F18)*(LN((F5+F19)/F5)))))/1000)) | D16: =IF(F19=0,((2*3.14*(F9)*(F15-F16))/((1/F17)*(LN(F5/F6))))/1000,((2*3.14*(F9)*(F15-F16))/(((1/F17)*(LN(F5/F6))+((1/F18)*(LN((F5+2*F19)/F5)))))/1000)) | E16: alterado | F16: Isolante: diâmetro externo = F5+2*F19 (era F5+F19)
