Workbook

Sheet Cálculo
A1: Dimensionamento — Apoio à Gás
A2: Vazão do sistema (3 métodos) + seleção de aquecedor · @ferretoengenharia
A4: ► PAINEL DE SELEÇÃO DO AQUECEDOR — CUSTO × BENEFÍCIO
A5: Método | B5: Pot. útil necessária (kcal/h) | C5: Arranjo recomendado | D5: Preço | E5: Pot. útil do arranjo (kcal/h) | F5: Pot. nominal do arranjo (kcal/h) | G5: Alternativa (quando vale a pena)
A6: Vazão Máxima Provável (V.M.P) | B6: =B24 -> 43200 | C6: =IF($O6=0,"sem opção",IF($O6=1,"✓ 1× "&SUBSTITUTE(INDEX(Aquecedores!$B$3:$B$10,$K6),"RINNAI ",""),"✓ 2× "&SUBSTITUTE(INDEX(Aquecedores!$B$3:$B$10,$L6),"RINNAI ",""))) -> ✓ 2× E21 | D6: =IF($O6=1,$M6,IF($O6=2,$N6,"")) -> 5998 | E6: =IF($O6=1,INDEX(Aquecedores!$H$3:$H$10,$K6),IF($O6=2,2*INDEX(Aquecedores!$H$3:$H$10,$L6),"")) -> 49880 | F6: =IF($O6=1,INDEX(Aquecedores!$D$3:$D$10,$K6),IF($O6=2,2*INDEX(Aquecedores!$D$3:$D$10,$L6),"")) -> 58000 | G6: =IF(AND($O6=2,$K6<=8),"1× "&SUBSTITUTE(INDEX(Aquecedores!$B$3:$B$10,$K6),"RINNAI ","")&" · +R$ "&TEXT($M6-$N6,"#,##0")&" (1 aparelho)","—") -> 1× E43 · +R$ 4472,0 (1 aparelho) | K6: =SUMPRODUCT((Aquecedores!$H$3:$H$10<$B6)*1)+1 -> 8 | L6: =SUMPRODUCT((Aquecedores!$H$3:$H$10<$B6/2)*1)+1 -> 4 | M6: =IFERROR(INDEX(Aquecedores!$G$3:$G$10,$K6),"") -> 10470 | N6: =IFERROR(2*INDEX(Aquecedores!$G$3:$G$10,$L6),"") -> 5998 | O6: =IF(AND($K6<=8,$L6<=8),IF($N6<$M6,2,1),IF($K6<=8,1,IF($L6<=8,2,0))) -> 2
A7: NBR 16057 | B7: =B34 -> 12000 | C7: =IF($O7=0,"sem opção",IF($O7=1,"✓ 1× "&SUBSTITUTE(INDEX(Aquecedores!$B$3:$B$10,$K7),"RINNAI ",""),"✓ 2× "&SUBSTITUTE(INDEX(Aquecedores!$B$3:$B$10,$L7),"RINNAI ",""))) -> ✓ 1× E10 | D7: =IF($O7=1,$M7,IF($O7=2,$N7,"")) -> 1549 | E7: =IF($O7=1,INDEX(Aquecedores!$H$3:$H$10,$K7),IF($O7=2,2*INDEX(Aquecedores!$H$3:$H$10,$L7),"")) -> 12470 | F7: =IF($O7=1,INDEX(Aquecedores!$D$3:$D$10,$K7),IF($O7=2,2*INDEX(Aquecedores!$D$3:$D$10,$L7),"")) -> 14500 | G7: =IF(AND($O7=2,$K7<=8),"1× "&SUBSTITUTE(INDEX(Aquecedores!$B$3:$B$10,$K7),"RINNAI ","")&" · +R$ "&TEXT($M7-$N7,"#,##0")&" (1 aparelho)","—") -> — | K7: =SUMPRODUCT((Aquecedores!$H$3:$H$10<$B7)*1)+1 -> 1 | L7: =SUMPRODUCT((Aquecedores!$H$3:$H$10<$B7/2)*1)+1 -> 1 | M7: =IFERROR(INDEX(Aquecedores!$G$3:$G$10,$K7),"") -> 1549 | N7: =IFERROR(2*INDEX(Aquecedores!$G$3:$G$10,$L7),"") -> 3098 | O7: =IF(AND($K7<=8,$L7<=8),IF($N7<$M7,2,1),IF($K7<=8,1,IF($L7<=8,2,0))) -> 1
A8: Tempo Determinado (T.D) | B8: =B39 -> 3200 | C8: =IF($O8=0,"sem opção",IF($O8=1,"✓ 1× "&SUBSTITUTE(INDEX(Aquecedores!$B$3:$B$10,$K8),"RINNAI ",""),"✓ 2× "&SUBSTITUTE(INDEX(Aquecedores!$B$3:$B$10,$L8),"RINNAI ",""))) -> ✓ 1× E10 | D8: =IF($O8=1,$M8,IF($O8=2,$N8,"")) -> 1549 | E8: =IF($O8=1,INDEX(Aquecedores!$H$3:$H$10,$K8),IF($O8=2,2*INDEX(Aquecedores!$H$3:$H$10,$L8),"")) -> 12470 | F8: =IF($O8=1,INDEX(Aquecedores!$D$3:$D$10,$K8),IF($O8=2,2*INDEX(Aquecedores!$D$3:$D$10,$L8),"")) -> 14500 | G8: =IF(AND($O8=2,$K8<=8),"1× "&SUBSTITUTE(INDEX(Aquecedores!$B$3:$B$10,$K8),"RINNAI ","")&" · +R$ "&TEXT($M8-$N8,"#,##0")&" (1 aparelho)","—") -> — | K8: =SUMPRODUCT((Aquecedores!$H$3:$H$10<$B8)*1)+1 -> 1 | L8: =SUMPRODUCT((Aquecedores!$H$3:$H$10<$B8/2)*1)+1 -> 1 | M8: =IFERROR(INDEX(Aquecedores!$G$3:$G$10,$K8),"") -> 1549 | N8: =IFERROR(2*INDEX(Aquecedores!$G$3:$G$10,$L8),"") -> 3098 | O8: =IF(AND($K8<=8,$L8<=8),IF($N8<$M8,2,1),IF($K8<=8,1,IF($L8<=8,2,0))) -> 1
A9: ="Preços médios levantados em "&Aquecedores!$D$12&" · referenciais · 2 aparelhos = em paralelo (não inclui instalação/ponto de gás/exaustão extras)" -> Preços médios levantados em 21/06/2026 · referenciais · 2 aparelhos = em paralelo (não inclui instalação/ponto de gás/exaustão extras)
A11: DADOS DE ENTRADA (edite as células amarelas)
A12: VB — vazão de uso | B12: 36 | C12: l/min | D12: ex.: 3 banhos ~ 12 l/min cada
A13: TB — temp. de uso | B13: 40 | C13: °C
A14: TAF — temp. água fria | B14: 20 | C14: °C
A15: TAQ — temp. do boiler | B15: 50 | C15: °C
A16: V consumo diário (NBR) | B16: 1000 | C16: L
A17: FS — simultaneidade (NBR) | B17: 0.9 | C17: — | D17: 0,9 p/ unidade habitacional
A18: V — volume do boiler (T.D) | B18: 1000 | C18: L
A19: t — tempo analisado (T.D) | B19: 15 | C19: min
A20: ΔT = TAQ − TAF | B20: =B15-B14 -> 30 | C20: °C | D20: calculado
A22: MÉTODO 1 — VAZÃO MÁXIMA PROVÁVEL (V.M.P) | H22: Tabela C.1 — F armaz
A23: VAQ | B23: =B12*(B13-B14)/(B15-B14) -> 24 | C23: l/min | D23: ƒ: VB × (TB−TAF)/(TAQ−TAF) | H23: V pico (L) | I23: F armaz
A24: P (potência útil) | B24: =B23*B20*60 -> 43200 | C24: kcal/h | D24: ƒ: VAQ × ΔT × 60 | H24: 0 a 1 500 | I24: 1/3
A25: vazão (l/h) | B25: =B24/B20 -> 1440 | C25: l/h | H25: 1 501 a 6 000 | I25: 1/4
A26: ► Vazão V.M.P | B26: =B25/60 -> 24 | C26: l/min | H26: 6 001 a 12 000 | I26: 1/5
H27: 12 001 a 20 000 | I27: 1/6
A28: MÉTODO 2 — NBR 16057 (SAAG) | H28: > 20 001 | I28: 1/7
A29: V corrigido | B29: =B16*(B13-B14)/(B15-B14) -> 666.66667 | C29: L | D29: ƒ: Vcons × (TB−TAF)/(TAQ−TAF)
A30: V pico | B30: =B29*B17 -> 600 | C30: L | D30: ƒ: V corrigido × FS | H30: ABNT NBR 16057:2024, Anexo C
A31: F armaz | B31: =IF(B30<=1500,1/3,IF(B30<=6000,1/4,IF(B30<=12000,1/5,IF(B30<=20000,1/6,1/7)))) -> 0.33333333 | C31: — | D31: Tabela C.1 (por V pico)
A32: V armaz. gás | B32: =B30*B31 -> 200 | C32: L | D32: ƒ: V pico × F armaz
A33: V recup. | B33: =B30-B32 -> 400 | C33: L | D33: ƒ: V pico − V armaz. gás
A34: P (potência útil) | B34: =B33*B20 -> 12000 | C34: kcal/h | D34: ƒ: V recup. × ΔT
A35: vazão (l/h) | B35: =B34/B20 -> 400 | C35: l/h
A36: ► Vazão NBR 16057 | B36: =B35/60 -> 6.6666667 | C36: l/min
A38: MÉTODO 3 — TEMPO DETERMINADO (T.D)
A39: P (potência útil) | B39: =((B12*(B13-B14)*B19)-(B18*(B15-B13)))*60/B19 -> 3200 | C39: kcal/h | D39: ƒ: [(VB×(TB−TAF)×t) − (V×(TAQ−TB))]×60/t
A40: vazão (l/h) | B40: =B39/B20 -> 106.66667 | C40: l/h
A41: ► Vazão Tempo Determinado | B41: =B40/60 -> 1.7777778 | C41: l/min
A43: RESUMO — VAZÕES DO SISTEMA
A44: Vazão Máxima Provável (V.M.P) | B44: =B26 -> 24 | C44: l/min
A45: NBR 16057 | B45: =B36 -> 6.6666667 | C45: l/min
...

Sheet Aquecedores
B1: AQUECEDORES RINNAI — CATÁLOGO DE REFERÊNCIA
B2: Modelo | C2: Vazão (L/min) | D2: Pot. nominal (kcal/h) | E2: Pot. (kW) | F2: Rendimento | G2: Preço médio (R$) | H2: Pot. útil (kcal/h)
B3: RINNAI E10 | C3: 10 | D3: 14500 | E3: 16.8 | F3: 0.86 | G3: 1549 | H3: =D3*F3 -> 12470
B4: RINNAI E15 | C4: 15 | D4: 21000 | E4: 24.4 | F4: 0.86 | G4: 1900 | H4: =D4*F4 -> 18060
B5: RINNAI E17 | C5: 17 | D5: 23800 | E5: 27.7 | F5: 0.86 | G5: 2499 | H5: =D5*F5 -> 20468
B6: RINNAI E21 | C6: 21 | D6: 29000 | E6: 33.7 | F6: 0.86 | G6: 2999 | H6: =D6*F6 -> 24940
B7: RINNAI E27 | C7: 27 | D7: 37700 | E7: 43.8 | F7: 0.86 | G7: 3540 | H7: =D7*F7 -> 32422
B8: RINNAI E33 | C8: 32.5 | D8: 45300 | E8: 52.7 | F8: 0.86 | G8: 4409 | H8: =D8*F8 -> 38958
B9: RINNAI E35 | C9: 35 | D9: 49130 | E9: 57.1 | F9: 0.85 | G9: 4735 | H9: =D9*F9 -> 41760.5
B10: RINNAI E43 | C10: 45 | D10: 62800 | E10: 73 | F10: 0.86 | G10: 10470 | H10: =D10*F10 -> 54008
B12: Preços levantados em: | D12: 21/06/2026
B13: Valores médios de mercado, de caráter referencial. Atualize a data ao revisar os preços.
